Workbook

Sheet CUSTOMERS
A1: Customer_ID | B1: First_Name | C1: Last_Name | D1: Email
A2: 1 | B2: George | C2: Gonzalez | D2: george.gonzalez1@gmail.com
A3: 2 | B3: Quinn | C3: Martin | D3: quinn.martin2@bgu.net
A4: 3 | B4: Quinn | C4: Moore | D4: quinn.moore3@outlook.org
A5: 4 | B5: Charlie | C5: Garcia | D5: charlie.garcia4@gmail.com
A6: 5 | B6: Hannah | C6: Thomas | D6: hannah.thomas5@hotmail.com
A7: 6 | B7: Laura | C7: Taylor | D7: laura.taylor6@bgu.net
A8: 7 | B8: Julia | C8: Davis | D8: julia.davis7@gmail.com
A9: 8 | B9: Steve | C9: Davis | D9: steve.davis8@bgu.net
A10: 9 | B10: Michael | C10: Moore | D10: michael.moore9@gmail.com
A11: 10 | B11: Michael | C11: Taylor | D11: michael.taylor10@hotmail.com
A12: 11 | B12: Ethan | C12: Wilson | D12: ethan.wilson11@bgu.net
A13: 12 | B13: Charlie | C13: Wilson | D13: charlie.wilson12@gmail.com
... A251: 250 | B251: Nina | C251: Anderson | D251: nina.anderson250@outlook.org

Sheet CREDIT_CARDS
A1: Card_Number | B1: Expiration_Date | C1: CCV | D1: Name_On_Card | E1: Customer_ID
A2: 2720-0475-9030-3034 | B2: 45962 | C2: 509 | D2: =CUSTOMERS!B2&" "&CUSTOMERS!C2 -> George Gonzalez | E2: 1
A3: 5255-5661-7425-6777 | B3: 46692 | C3: 626 | D3: =CUSTOMERS!B3&" "&CUSTOMERS!C3 -> Quinn Martin | E3: 2
A4: 5113-8721-5441-1024 | B4: 46266 | C4: 989 | D4: =CUSTOMERS!B4&" "&CUSTOMERS!C4 -> Quinn Moore | E4: 3
A5: 2720-3096-9040-0965 | B5: 46357 | C5: 947 | D5: =CUSTOMERS!B5&" "&CUSTOMERS!C5 -> Charlie Garcia | E5: 4
A6: 2484-0564-3023-3190 | B6: 46631 | C6: 793 | D6: =CUSTOMERS!B6&" "&CUSTOMERS!C6 -> Hannah Thomas | E6: 5
A7: 5525-3953-4829-5246 | B7: 46539 | C7: 175 | D7: =CUSTOMERS!B7&" "&CUSTOMERS!C7 -> Laura Taylor | E7: 6
A8: 2690-5581-2914-3564 | B8: 46600 | C8: 966 | D8: =CUSTOMERS!B8&" "&CUSTOMERS!C8 -> Julia Davis | E8: 7
A9: 5371-5229-0768-4925 | B9: 46508 | C9: 198 | D9: =CUSTOMERS!B9&" "&CUSTOMERS!C9 -> Steve Davis | E9: 8
A10: 2343-4947-4242-5348 | B10: 46569 | C10: 912 | D10: =CUSTOMERS!B10&" "&CUSTOMERS!C10 -> Michael Moore | E10: 9
A11: 2511-2235-0417-1188 | B11: 45901 | C11: 278 | D11: =CUSTOMERS!B11&" "&CUSTOMERS!C11 -> Michael Taylor | E11: 10
A12: 2669-0481-5683-5123 | B12: 45839 | C12: 864 | D12: =CUSTOMERS!B12&" "&CUSTOMERS!C12 -> Ethan Wilson | E12: 11
A13: 2720-8776-6417-6423 | B13: 46692 | C13: 999 | D13: =CUSTOMERS!B13&" "&CUSTOMERS!C13 -> Charlie Wilson | E13: 12
... A251: 2381-7357-6347-1220 | B251: 45839 | C251: 662 | D251: =CUSTOMERS!B251&" "&CUSTOMERS!C251 -> Nina Anderson | E251: 250

Sheet SEARCHES
A1: DT | B1: IP_Address | C1: Text | D1: Customer_ID
A2: 2022-02-02 21:10 | B2: 252.213.204.93 | C2: blue light blocking glasses | D2: 87
A3: 2023-09-20 07:43 | B3: 171.39.3.178 | C3: mens aviator sunglasses | D3: 44
A4: 2021-11-09 12:04 | B4: 212.218.82.39 | C4: cat eye sunglasses women | D4: 41
A5: 2023-06-19 08:10 | B5: 128.244.187.107 | C5: kids prescription glasses | D5: 124
A6: 2021-12-29 02:22 | B6: 75.139.20.54 | C6: round glasses frame | D6: 215
A7: 2021-06-02 06:10 | B7: 77.147.147.5 | C7: ray ban wayfarer | D7: 115
A8: 2023-04-08 16:47 | B8: 164.206.181.64 | C8: cheap prescription glasses | D8: 6
A9: 2025-01-18 02:47 | B9: 252.36.146.170 | C9: polarized sunglasses for fishing | D9: 249
A10: 2023-04-12 17:23 | B10: 83.249.106.102 | C10: transition lenses | D10: 101
A11: 2021-09-26 16:25 | B11: 20.203.115.156 | C11: oversized sunglasses | D11: 191
A12: 2022-11-03 04:34 | B12: 52.137.92.141 | C12: tortoise shell frame glasses | D12: 127
A13: 2024-10-12 06:21 | B13: 253.121.162.230 | C13: sport sunglasses for running | D13: 200
... A484: 2021-02-02 18:02 | B484: 177.16.126.174 | C484: unisex fashion sunglasses for men and women | D484: 97

Sheet ORDERS
A1: Order_ID | B1: Date | C1: Country | D1: City | E1: Street_Name | F1: Street_Number | G1: Apartment | H1: ZIP_Code | I1: Prescription | J1: Card_Number
A2: 1 | B2: 44594 | C2: USA | D2: New York | E2: Lexington Ave | F2: 214 | G2: 3 | H2: 10016 | I2: https://uploadedpicture.com/prescription1.jpg | J2: =CREDIT_CARDS!A2 -> 2720-0475-9030-3034
A3: 2 | B3: 45189 | C3: Canada | D3: Toronto | E3: Bloor St W | F3: 334 | G3: 17 | H3: M5S1W7 | I3: https://uploadedpicture.com/prescription2.jpg | J3: =CREDIT_CARDS!A3 -> 5255-5661-7425-6777
A4: 3 | B4: 44509 | C4: UK | D4: London | E4: Baker St | F4: 221 | G4: 16 | H4: NW16XE | I4: https://uploadedpicture.com/prescription3.jpg | J4: =CREDIT_CARDS!A4 -> 5113-8721-5441-1024
A5: 4 | B5: 45096 | C5: Germany | D5: Berlin | E5: Kurfürstendamm | F5: 150 | G5: 5 | H5: 10709 | I5: https://uploadedpicture.com/prescription4.jpg | J5: =CREDIT_CARDS!A5 -> 2720-3096-9040-0965
A6: 5 | B6: 44559 | C6: France | D6: Paris | E6: Rue de Rivoli | F6: 98 | G6: 2 | H6: 75001 | I6: https://uploadedpicture.com/prescription5.jpg | J6: =CREDIT_CARDS!A6 -> 2484-0564-3023-3190
A7: 6 | B7: 44349 | C7: Italy | D7: Rome | E7: Via del Corso | F7: 75 | G7: 52 | H7: 187 | I7: https://uploadedpicture.com/prescription6.jpg | J7: =CREDIT_CARDS!A7 -> 5525-3953-4829-5246
A8: 7 | B8: 45024 | C8: USA | D8: San Francisco | E8: Market St | F8: 101 | G8: 7 | H8: 94103 | I8: https://uploadedpicture.com/prescription7.jpg | J8: =CREDIT_CARDS!A8 -> 2690-5581-2914-3564
A9: 8 | B9: 45675 | C9: Netherlands | D9: Amsterdam | E9: Keizersgracht | F9: 321 | G9: 32 | H9: 1016EJ | I9: https://uploadedpicture.com/prescription8.jpg | J9: =CREDIT_CARDS!A9 -> 5371-5229-0768-4925
A10: 9 | B10: 45028 | C10: Spain | D10: Madrid | E10: Gran Via | F10: 57 | G10: 1 | H10: 28013 | I10: https://uploadedpicture.com/prescription9.jpg | J10: =CREDIT_CARDS!A10 -> 2343-4947-4242-5348
A11: 10 | B11: 44465 | C11: Australia | D11: Sydney | E11: George St | F11: 480 | G11: 9 | H11: 2000 | I11: https://uploadedpicture.com/prescription10.jpg | J11: =CREDIT_CARDS!A11 -> 2511-2235-0417-1188
A12: 11 | B12: 44868 | C12: USA | D12: Chicago | E12: Wacker Dr | F12: 200 | G12: 6 | H12: 60606 | I12: https://uploadedpicture.com/prescription11.jpg | J12: =CREDIT_CARDS!A12 -> 2669-0481-5683-5123
A13: 12 | B13: 45577 | C13: Sweden | D13: Stockholm | E13: Drottninggatan | F13: 88 | G13: 8 | H13: 11136 | I13: https://uploadedpicture.com/prescription12.jpg | J13: =CREDIT_CARDS!A13 -> 2720-8776-6417-6423
A14: 13 | B14: 45729 | C14: Norway | D14: Oslo | E14: Karl Johans gate | F14: 55 | G14: 4 | H14: 162 | I14: https://uploadedpicture.com/prescription13.jpg | J14: =CREDIT_CARDS!A14 -> 2720-3477-2001-4612
A15: 14 | B15: 45438 | C15: Japan | D15: Tokyo | E15: Shibuya St | F15: 133 | G15: 11 | H15: 150 | I15: https://uploadedpicture.com/prescription14.jpg | J15: =CREDIT_CARDS!A15 -> 2578-7428-5997-9283
A16: 15 | B16: 45279 | C16: USA | D16: Boston | E16: Beacon St | F16: 12 | G16: 66 | H16: 2108 | I16: https://uploadedpicture.com/prescription15.jpg | J16: =CREDIT_CARDS!A16 -> 5174-6553-9288-9234
A17: 16 | B17: 45607 | C17: UK | D17: Manchester | E17: King St | F17: 45 | G17: 8 | H17: M2N6E2 | I17: https://uploadedpicture.com/prescription16.jpg | J17: =CREDIT_CARDS!A17 -> 5521-1490-7531-1047
A18: 17 | B18: 45658 | C18: Canada | D18: Vancouver | E18: Granville St | F18: 78 | G18: 21 | H18: V6B1G1 | I18: https://uploadedpicture.com/prescription17.jpg | J18: =CREDIT_CARDS!A18 -> 5193-1099-3515-3978
A19: 18 | B19: 45491 | C19: France | D19: Lyon | E19: Rue Saint Paul | F19: 16 | G19: 3 | H19: 69005 | I19: https://uploadedpicture.com/prescription18.jpg | J19: =CREDIT_CARDS!A19 -> 2677-8549-1028-8008
A20: 19 | B20: 45180 | C20: Germany | D20: Munich | E20: Leopoldstrasse | F20: 89 | G20: 102 | H20: 80331 | I20: https://uploadedpicture.com/prescription19.jpg | J20: =CREDIT_CARDS!A20 -> 5430-2290-1984-9854
A21: 20 | B21: 45567 | C21: Italy | D21: Milan | E21: Via Roma | F21: 23 | G21: 7 | H21: 20121 | I21: https://uploadedpicture.com/prescription20.jpg | J21: =CREDIT_CARDS!A21 -> 5433-1124-4366-2829
A22: 21 | B22: 45461 | C22: Spain | D22: Barcelona | E22: Carrer de Balmes | F22: 47 | G22: 55 | H22: 8007 | I22: https://uploadedpicture.com/prescription21.jpg | J22: =CREDIT_CARDS!A22 -> 5137-7730-3092-1602
A23: 22 | B23: 45783 | C23: Australia | D23: Melbourne | E23: Collins St | F23: 322 | G23: 2 | H23: 3000 | I23: https://uploadedpicture.com/prescription22.jpg | J23: =CREDIT_CARDS!A23 -> 2582-3562-0389-5287
A24: 23 | B24: 44453 | C24: USA | D24: Houston | E24: Main St | F24: 150 | G24: 4 | H24: 77002 | I24: https://uploadedpicture.com/prescription23.jpg | J24: =CREDIT_CARDS!A24 -> 2505-4125-7169-9860
A25: 24 | B25: 44655 | C25: UK | D25: Bristol | E25: Queens Rd | F25: 10 | G25: 4 | H25: BS8 1RF | I25: https://uploadedpicture.com/prescription24.jpg | J25: =CREDIT_CARDS!A25 -> 2478-8346-3989-6126
A26: 25 | B26: 45078 | C26: Canada | D26: Montreal | E26: St Catherine St | F26: 87 | G26: 280 | H26: H3B 1A7 | I26: https://uploadedpicture.com/prescription25.jpg | J26: =CREDIT_CARDS!A26 -> 2221-9700-5948-0049
A27: 26 | B27: 45490 | C27: USA | D27: Philadelphia | E27: Walnut St | F27: 37 | G27: 15 | H27: 19103 | I27: https://uploadedpicture.com/prescription26.jpg | J27: =CREDIT_CARDS!A27 -> 2637-7378-7841-7355
A28: 27 | B28: 45096 | C28: France | D28: Lille | E28: Rue Faidherbe | F28: 29 | G28: 7 | H28: 59000 | I28: https://uploadedpicture.com/prescription27.jpg | J28: =CREDIT_CARDS!A28 -> 5309-0853-5117-9864
A29: 28 | B29: 44349 | C29: Germany | D29: Hamburg | E29: Mönckebergstraße | F29: 42 | G29: 40 | H29: 20095 | I29: https://uploadedpicture.com/prescription28.jpg | J29: =CREDIT_CARDS!A29 -> 5219-8703-7043-9301
A30: 29 | B30: 45381 | C30: UK | D30: Birmingham | E30: Chester Rd | F30: 221 | G30: 4 | H30: B42 2LF | I30: https://uploadedpicture.com/prescription29.jpg | J30: =CREDIT_CARDS!A30 -> 2438-8027-5237-8478
A31: 30 | B31: 44840 | C31: Canada | D31: Montreal | E31: Saint Catherine St | F31: 56 | G31: 2 | H31: H3B 1H5 | I31: https://uploadedpicture.com/prescription30.jpg | J31: =CREDIT_CARDS!A31 -> 5559-4629-9252-9012
A32: 31 | B32: 44931 | C32: Italy | D32: Naples | E32: Via Toledo | F32: 83 | G32: 72 | H32: 80139 | I32: https://uploadedpicture.com/prescription31.jpg | J32: =CREDIT_CARDS!A32 -> 2221-4827-1617-8560
A33: 32 | B33: 44550 | C33: Spain | D33: Seville | E33: Calle Tetuán | F33: 101 | G33: 16 | H33: 41001 | I33: https://uploadedpicture.com/prescription32.jpg | J33: =CREDIT_CARDS!A33 -> 2720-7932-6049-0698
A34: 33 | B34: 45056 | C34: Netherlands | D34: Rotterdam | E34: Coolsingel | F34: 152 | G34: 5 | H34: 3011 AA | I34: https://uploadedpicture.com/prescription33.jpg | J34: =CREDIT_CARDS!A34 -> 5267-2016-8751-1221
A35: 34 | B35: 44393 | C35: USA | D35: Denver | E35: Lincoln St | F35: 78 | G35: 8 | H35: 80202 | I35: https://uploadedpicture.com/prescription34.jpg | J35: =CREDIT_CARDS!A35 -> 2720-6416-7031-1691
A36: 35 | B36: 44702 | C36: Australia | D36: Brisbane | E36: Queen St | F36: 243 | G36: 78 | H36: 4000 | I36: https://uploadedpicture.com/prescription35.jpg | J36: =CREDIT_CARDS!A36 -> 5358-4449-7474-4143
A37: 36 | B37: 45023 | C37: UK | D37: Leeds | E37: Park Row | F37: 36 | G37: 3 | H37: LS1 5HY | I37: https://uploadedpicture.com/prescription36.jpg | J37: =CREDIT_CARDS!A37 -> 5558-9652-3421-6959
A38: 37 | B38: 45227 | C38: Canada | D38: Ottawa | E38: Elgin St | F38: 54 | G38: 12 | H38: K1P 5M8 | I38: https://uploadedpicture.com/prescription37.jpg | J38: =CREDIT_CARDS!A38 -> 5225-6661-5794-7439
A39: 38 | B39: 44446 | C39: France | D39: Nice | E39: Avenue Jean Médecin | F39: 41 | G39: 6 | H39: 6000 | I39: https://uploadedpicture.com/prescription38.jpg | J39: =CREDIT_CARDS!A39 -> 5125-5566-9719-9289
A40: 39 | B40: 44584 | C40: Germany | D40: Cologne | E40: Hohe Strasse | F40: 112 | G40: 88 | H40: 50667 | I40: https://uploadedpicture.com/prescription39.jpg | J40: =CREDIT_CARDS!A40 -> 5305-7690-3843-4024
...

Sheet PRODUCTS
A1: Product_ID | B1: Name | C1: Description | D1: Rating | E1: Price
A2: 1 | B2: The Gemstone | C2: Top Frame in blue camo pattern. | D2: =AVERAGEIF(REVIEWS!G:G, A2, REVIEWS!E:E) -> 3.4 | E2: 25
A3: 2 | B3: The Black | C3: A top frame for those who wants to stay classy. | D3: =AVERAGEIF(REVIEWS!G:G, A3, REVIEWS!E:E) -> 1 | E3: 30
A4: 3 | B4: The Navy | C4: A top frame for true lovers of the sea. | D4: =AVERAGEIF(REVIEWS!G:G, A4, REVIEWS!E:E) -> 3.6666667 | E4: 28
A5: 4 | B5: Glasses Case | C5: Our protective glasses case will make you feel safer. | D5: =AVERAGEIF(REVIEWS!G:G, A5, REVIEWS!E:E) -> 4 | E5: 20
A6: 5 | B6: The Kirby | C6: This medium rectangle frame is stylish and timeless. | D6: =AVERAGEIF(REVIEWS!G:G, A6, REVIEWS!E:E) -> 2.6666667 | E6: 70
A7: 6 | B7: The Larkin | C7: This narrow, modified rectangle frame is a fan-favorite. | D7: =AVERAGEIF(REVIEWS!G:G, A7, REVIEWS!E:E) -> 1 | E7: 70
A8: 7 | B8: The Murphy | C8: This wide frame has an oversized, new-fashioned feel. | D8: =AVERAGEIF(REVIEWS!G:G, A8, REVIEWS!E:E) -> 2 | E8: 70
A9: 8 | B9: The Finley | C9: This narrow frame is extremely versatile and effortlessly cool. | D9: =AVERAGEIF(REVIEWS!G:G, A9, REVIEWS!E:E) -> 3 | E9: 70
A10: 9 | B10: The Falcon | C10: Blue-tinted top frame with a sleek design. | D10: =AVERAGEIF(REVIEWS!G:G, A10, REVIEWS!E:E) -> 3.5 | E10: 65
A11: 10 | B11: The Orion | C11: A timeless frame with subtle detailing. | D11: =AVERAGEIF(REVIEWS!G:G, A11, REVIEWS!E:E) -> 2 | E11: 60
A12: 11 | B12: The Voyager | C12: Durable frame for the adventurous spirit. | D12: =AVERAGEIF(REVIEWS!G:G, A12, REVIEWS!E:E) -> 5 | E12: 75
A13: 12 | B13: The Eclipse | C13: Modern frame with a matte finish. | D13: =AVERAGEIF(REVIEWS!G:G, A13, REVIEWS!E:E) -> 2.6666667 | E13: 70
... A135: 134 | B135: The Zenithal | C135: Highest peak design with sharp angles. | D135: =AVERAGEIF(REVIEWS!G:G, A135, REVIEWS!E:E) -> 2.6666667 | E135: 84

Sheet SEARCHES_FOR_PRODUCTS
A1: Product_ID | B1: DT | C1: IP_Address
A2: 25 | B2: =SEARCHES!A2 -> 2022-02-02 21:10 | C2: =SEARCHES!B2 -> 252.213.204.93
A3: 30 | B3: =SEARCHES!A3 -> 2023-09-20 07:43 | C3: =SEARCHES!B3 -> 171.39.3.178
A4: 35 | B4: =SEARCHES!A4 -> 2021-11-09 12:04 | C4: =SEARCHES!B4 -> 212.218.82.39
A5: 22 | B5: =SEARCHES!A5 -> 2023-06-19 08:10 | C5: =SEARCHES!B5 -> 128.244.187.107
A6: 74 | B6: =SEARCHES!A6 -> 2021-12-29 02:22 | C6: =SEARCHES!B6 -> 75.139.20.54
A7: 122 | B7: =SEARCHES!A7 -> 2021-06-02 06:10 | C7: =SEARCHES!B7 -> 77.147.147.5
A8: 15 | B8: =SEARCHES!A8 -> 2023-04-08 16:47 | C8: =SEARCHES!B8 -> 164.206.181.64
A9: 97 | B9: =SEARCHES!A9 -> 2025-01-18 02:47 | C9: =SEARCHES!B9 -> 252.36.146.170
A10: 64 | B10: =SEARCHES!A10 -> 2023-04-12 17:23 | C10: =SEARCHES!B10 -> 83.249.106.102
A11: 89 | B11: =SEARCHES!A11 -> 2021-09-26 16:25 | C11: =SEARCHES!B11 -> 20.203.115.156
A12: 39 | B12: =SEARCHES!A12 -> 2022-11-03 04:34 | C12: =SEARCHES!B12 -> 52.137.92.141
A13: 87 | B13: =SEARCHES!A13 -> 2024-10-12 06:21 | C13: =SEARCHES!B13 -> 253.121.162.230
... A345: 121 | B345: =SEARCHES!A345 -> 2020-03-19 12:51 | C345: =SEARCHES!B345 -> 79.60.219.96

Sheet ORDERABLE_PRODUCTS
A1: Product_ID
A2: 1
A3: 2
A4: 3
A5: 4
A6: 9
A7: 17
A8: 18
A9: 19
A10: 21
A11: 26
A12: 36
A13: 52
... A47: 133

Sheet COLORS
A1: Color
A2: Black
A3: White
A4: Red
A5: Blue
A6: Green
A7: Yellow
A8: Orange
A9: Purple
A10: Brown
A11: Gray
A12: Pink
... A52: Chocolate

Sheet TOP_FRAMES
A1: Product_ID | B1: Color | C1: Design
A2: 1 | B2: Black | C2: Classic
A3: 2 | B3: White | C3: Minimalist
A4: 3 | B4: Red | C4: Vibrant
A5: 9 | B5: Blue | C5: Oceanic
A6: 21 | B6: Green | C6: Forest
A7: 96 | B7: Yellow | C7: Sunny
A8: 97 | B8: Orange | C8: Bold
A9: 98 | B9: Purple | C9: Regal
A10: 99 | B10: Brown | C10: Rustic
A11: 100 | B11: Gray | C11: Modern
A12: 110 | B12: Pink | C12: Playful
A13: 111 | B13: Navy Blue | C13: Nautical
... A35: 133 | B35: Burgundy | C35: Rich

Sheet ORDERED
A1: Product_ID | B1: Order_ID | C1: Units
A2: 4 | B2: 1 | C2: 3
A3: 17 | B3: 2 | C3: 1
A4: 26 | B4: 2 | C4: 4
A5: 52 | B5: 3 | C5: 2
A6: 74 | B6: 3 | C6: 1
A7: 96 | B7: 4 | C7: 5
A8: 110 | B8: 5 | C8: 2
A9: 117 | B9: 5 | C9: 3
A10: 21 | B10: 6 | C10: 1
A11: 18 | B11: 6 | C11: 4
A12: 133 | B12: 7 | C12: 1
A13: 67 | B13: 7 | C13: 2
... A880: 36 | B880: 447 | C880: 1

Sheet BASE_FRAMES
A1: Product_ID | B1: Size | C1: Shape | D1: Gender
A2: 5 | B2: Extra Narrow | C2: Rectangular | D2: F
A3: 6 | B3: Narrow | C3: Rectangular | D3: F
A4: 7 | B4: Medium | C4: Rectangular | D4: M
A5: 8 | B5: Wide | C5: Rectangular | D5: M
A6: 10 | B6: Medium | C6: Rectangular | D6: M
A7: 11 | B7: Medium | C7: Rectangular | D7: M
A8: 12 | B8: Narrow | C8: Rectangular | D8: M
A9: 13 | B9: Medium | C9: Rectangular | D9: F
A10: 14 | B10: Wide | C10: Rectangular | D10: F
A11: 15 | B11: Extra Wide | C11: Rectangular | D11: M
A12: 16 | B12: Extra Narrow | C12: Rectangular | D12: M
A13: 20 | B13: Narrow | C13: Rectangular | D13: M
... A89: 134 | B89: Medium | C89: Round | D89: F

Sheet VERSIONS
A1: Product_ID | B1: Version | C1: Description
A2: 5 | B2: 1 | C2: Material: Metal, Lens Color: Black
A3: 5 | B3: 2 | C3: Material: Acetate, Lens Color: Brown
A4: 5 | B4: 3 | C4: Material: Metal, Lenses: Single Vision, Lens Type: Premium, Lenses: Blue-Light Filtering
A5: 6 | B5: 1 | C5: Material: Acetate, Lenses: Progressive Lenses, Lens Type: Plus
A6: 6 | B6: 2 | C6: Material: Metal, Lenses: Readers, Lens Type: Standard
A7: 6 | B7: 3 | C7: Material: Acetate, Lenses: Non-Prescription, Lens Type: Premium
A8: 7 | B8: 1 | C8: Material: Metal, Lenses: Single Vision, Lens Type: Standard, Lenses: Light Responsive
A9: 7 | B9: 2 | C9: Material: Acetate, Lenses: Progressive Lenses, Lens Type: Plus
A10: 7 | B10: 3 | C10: Material: Material: Metal, Lenses: Readers, Lens Type: Standard
A11: 8 | B11: 1 | C11: Material: Acetate, Lenses: Single Vision, Lens Type: Plus, Lenses: Blue-Light Filtering
A12: 8 | B12: 2 | C12: Material: Metal, Lenses: Progressive Lenses, Lens Type: Premium
A13: 8 | B13: 3 | C13: Material: Acetate, Lenses: Readers, Lens Type: Plus
... A265: 134 | B265: 3 | C265: Material: Metal, Lens Color: Black

Sheet CUSTOMIZATIONS
A1: Feature | B1: Selection | C1: Extra_Price
A2: Material | B2: Metal | C2: 0
A3: Material | B3: Acetate | C3: 0
A4: Lenses | B4: Single Vision | C4: 0
A5: Lenses | B5: Progressive Lenses | C5: 199
A6: Lenses | B6: Readers | C6: 0
A7: Lenses | B7: Non-Prescription | C7: 0
A8: Lens Type | B8: Premium | C8: 59
A9: Lens Type | B9: Plus | C9: 39
A10: Lens Type | B10: Standard | C10: 0
A11: Lenses | B11: Blue-Light Filtering | C11: 49
A12: Lenses | B12: Light Responsive | C12: 149
A13: Lens Color | B13: Black | C13: 0
A14: Lens Color | B14: Brown | C14: 0

Sheet GLASSES_ORDERED
A1: Product_ID | B1: Version | C1: Order_ID | D1: Units
A2: 5 | B2: 1 | C2: 1 | D2: 1
A3: 5 | B3: 2 | C3: 2 | D3: 1
A4: 5 | B4: 3 | C4: 2 | D4: 1
A5: 6 | B5: 1 | C5: 3 | D5: 2
A6: 6 | B6: 2 | C6: 3 | D6: 1
A7: 6 | B7: 3 | C7: 4 | D7: 5
A8: 7 | B8: 1 | C8: 5 | D8: 2
A9: 7 | B9: 2 | C9: 5 | D9: 3
A10: 7 | B10: 3 | C10: 6 | D10: 1
A11: 8 | B11: 1 | C11: 6 | D11: 2
A12: 8 | B12: 2 | C12: 7 | D12: 1
A13: 8 | B13: 3 | C13: 7 | D13: 2
... A880: 40 | B880: 3 | C880: 447 | D880: 2

Sheet SELECTED
A1: Product_ID | B1: Version | C1: Feature | D1: Selection
A2: 5 | B2: 1 | C2: Material | D2: Metal
A3: 5 | B3: 1 | C3: Lens Color | D3: Black
A4: 5 | B4: 2 | C4: Material | D4: Acetate
A5: 5 | B5: 2 | C5: Lens Color | D5: Brown
A6: 5 | B6: 3 | C6: Material | D6: Metal
A7: 5 | B7: 3 | C7: Lenses | D7: Single Vision
A8: 5 | B8: 3 | C8: Lens Type | D8: Premium
A9: 6 | B9: 1 | C9: Material | D9: Acetate
A10: 6 | B10: 1 | C10: Lenses | D10: Progressive Lenses
A11: 6 | B11: 2 | C11: Lens Type | D11: Plus
A12: 6 | B12: 2 | C12: Material | D12: Metal
A13: 6 | B13: 3 | C13: Lenses | D13: Readers
... A823: 134 | B823: 3 | C823: Material | D823: Metal

Sheet REVIEWS
A1: Review_ID | B1: Date | C1: Headline | D1: Text | E1: Rating | F1: Customer_ID | G1: Product_ID
A2: 1 | B2: 43914 | C2: Waste of money. | D2: Seriously disappointed. It felt cheap and didn't last. Don't waste your money. | E2: 1 | F2: 37 | G2: 2
A3: 2 | B3: 43980 | C3: So comfortable! | D3: I'm really happy with this item. It's exactly as described and works perfectly. | E3: 5 | F3: 24 | G3: 23
A4: 3 | B4: 44683 | C4: Exceeded my expectations. | D4: Initially, I was skeptical, but this has proven to be a really good investment. | E4: 3 | F4: 93 | G4: 99
A5: 4 | B5: 43598 | C5: Waste of money. | D5: Seriously disappointed. It felt cheap and didn't last. Don't waste your money. | E5: 2 | F5: 241 | G5: 105
A6: 5 | B6: 45334 | C6: Decent, but nothing special. | D6: This product didn't meet my expectations. The quality is subpar and it broke after a week. | E6: 5 | F6: 46 | G6: 30
A7: 6 | B7: 46012 | C7: Easy to use. | D7: I'm really happy with this item. It's exactly as described and works perfectly. | E7: 2 | F7: 181 | G7: 17
A8: 7 | B8: 43682 | C8: Fantastic quality for the price. | D8: Absolutely fantastic! I can't believe how good this is. Highly recommend to everyone. | E8: 3 | F8: 95 | G8: 113
A9: 8 | B9: 44044 | C9: Love the design. | D9: Fairly standard. There are better options out there if you're willing to pay more. | E9: 3 | F9: 99 | G9: 62
A10: 9 | B10: 44597 | C10: Fantastic quality for the price. | D10: I've been using it daily and it's holding up well. Very satisfied with my purchase. | E10: 3 | F10: 188 | G10: 84
A11: 10 | B11: 44026 | C11: Just what I needed. | D11: Absolutely fantastic! I can't believe how good this is. Highly recommend to everyone. | E11: 5 | F11: 225 | G11: 112
A12: 11 | B12: 43806 | C12: Perfect fit. | D12: Seriously disappointed. It felt cheap and didn't last. Don't waste your money. | E12: 4 | F12: 116 | G12: 86
A13: 12 | B13: 45204 | C13: Worth every penny! | D13: I'm really happy with this item. It's exactly as described and works perfectly. | E13: 3 | F13: 191 | G13: 19
... A312: 311 | B312: 43839 | C312: Not bad, could be better. | D312: This product didn't meet my expectations. The quality is subpar and it broke after a week. | E312: 2 | F312: 237 | G312: 79
